<?xml version="1.0" ?>
<sdf version="1.6">
  <world name="robotaksi_world">
    <plugin filename="libignition-gazebo-physics-system.so" name="ignition::gazebo::systems::Physics"/>
    <plugin filename="libignition-gazebo-user-commands-system.so" name="ignition::gazebo::systems::UserCommands"/>
    <plugin filename="libignition-gazebo-scene-broadcaster-system.so" name="ignition::gazebo::systems::SceneBroadcaster"/>
    <light type="directional" name="sun">
      <cast_shadows>true</cast_shadows>
      <pose>0 0 10 0 0 0</pose>
      <diffuse>0.8 0.8 0.8 1</diffuse>
      <specular>0.2 0.2 0.2 1</specular>
      <direction>-0.5 0.1 -0.9</direction>
    </light>
    <model name="invisible_ground">
      <static>true</static>
      <pose>0 0 -0.01 0 0 0</pose>
      <link name="link">
        <collision name="collision">
          <geometry>
            <box>
              <size>2000 2000 0.01</size>
            </box>
          </geometry>
        </collision>
      </link>
    </model>
    <include>
      <uri>model://robotaksi_map</uri>
      <pose>0 0 0 0 0 0</pose>
    </include>
    <include>
      <uri>model://durak_sign</uri>
      <name>durak_1</name>
      <pose>29.0746 0.795691 0.0575 0 0 1.54575</pose>
    </include>
    <include>
      <uri>model://durak_sign</uri>
      <name>durak_2</name>
      <pose>48.4687 16.9535 0.0575 0 0 0</pose>
    </include>
    <include>
      <uri>model://durak_sign</uri>
      <name>durak_3</name>
      <pose>11.4296 -14.644 0.0575 0 0 0</pose>
    </include>
    <include>
      <uri>model://construction_cone</uri>
      <name>construction_cone_1</name>
      <pose>20.8 -20.7 -0.005 0 0 0</pose>
    </include>
    <include>
      <uri>model://construction_cone</uri>
      <name>construction_cone_2</name>
      <pose>25.3 -20.7 -0.005 0 0 0</pose>
    </include>
    <include>
      <uri>model://construction_cone</uri>
      <name>construction_cone_3</name>
      <pose>29.8 -20.7 -0.005 0 0 0</pose>
    </include>
    <include>
      <uri>model://construction_cone</uri>
      <name>construction_cone_4</name>
      <pose>34.3 -20.7 -0.005 0 0 0</pose>
    </include>

    <!-- ── TRAFİK LAMBASI 1  (10.7719, 0.6677) ters yön ── -->
    <include>
      <uri>model://traffic_light</uri>
      <name>tl_1</name>
      <pose>10.7719 0.6677 0 0 0 3.14159</pose>
    </include>
    <include>
      <uri>model://tl_lamp_red</uri>
      <name>tl1_red</name>
      <pose>10.0219 0.6677 4.30 0 0 0</pose>
    </include>
    <include>
      <uri>model://tl_lamp_yellow</uri>
      <name>tl1_yellow</name>
      <pose>0 0 -100 0 0 0</pose>
    </include>
    <include>
      <uri>model://tl_lamp_green</uri>
      <name>tl1_green</name>
      <pose>0 0 -100 0 0 0</pose>
    </include>

    <!-- ── TRAFİK LAMBASI 2  (18.8216, 33.5324) ── -->
    <include>
      <uri>model://traffic_light</uri>
      <name>tl_2</name>
      <pose>18.8216 33.5324 0 0 0 0</pose>
    </include>
    <include>
      <uri>model://tl_lamp_red</uri>
      <name>tl2_red</name>
      <pose>19.5716 33.5324 4.30 0 0 0</pose>
    </include>
    <include>
      <uri>model://tl_lamp_yellow</uri>
      <name>tl2_yellow</name>
      <pose>0 0 -100 0 0 0</pose>
    </include>
    <include>
      <uri>model://tl_lamp_green</uri>
      <name>tl2_green</name>
      <pose>0 0 -100 0 0 0</pose>
    </include>

    <!-- ── TRAFİK LAMBASI 3  (40.6710, 0.0121) ters yön ── -->
    <include>
      <uri>model://traffic_light</uri>
      <name>tl_3</name>
      <pose>40.6710 0.0121 0 0 0 3.14159</pose>
    </include>
    <include>
      <uri>model://tl_lamp_red</uri>
      <name>tl3_red</name>
      <pose>39.9210 0.0121 4.30 0 0 0</pose>
    </include>
    <include>
      <uri>model://tl_lamp_yellow</uri>
      <name>tl3_yellow</name>
      <pose>0 0 -100 0 0 0</pose>
    </include>
    <include>
      <uri>model://tl_lamp_green</uri>
      <name>tl3_green</name>
      <pose>0 0 -100 0 0 0</pose>
    </include>

    <model name='my_robot'>
      <pose>2.0 3.0 0.15 0 0 0</pose>
    <link name='base_footprint'>
      <inertial>
        <pose>0.0003793929712460063 0 0.3672963258785942 0 0 0</pose>
        <mass>500.80000000000001</mass>
        <inertia>
          <ixx>71.232659225239615</ixx>
          <ixy>0</ixy>
          <ixz>-0.18956369808306711</ixz>
          <iyy>131.4130871405751</iyy>
          <iyz>0</iyz>
          <izz>150.1817279153355</izz>
        </inertia>
      </inertial>
      <collision name='base_footprint_fixed_joint_lump__base_link_collision'>
        <pose>0 0 0.365 0 0 0</pose>
        <geometry>
          <box>
            <size>2 1.2 0.4</size>
          </box>
        </geometry>
      </collision>
      <collision name='base_footprint_fixed_joint_lump__camera_link_collision_1'>
        <pose>0.95 0 1.365 0 0.35 0</pose>
        <geometry>
          <box>
            <size>0.1 0.1 0.1</size>
          </box>
        </geometry>
        <surface>
          <contact>
            <ode/>
          </contact>
          <friction>
            <ode/>
          </friction>
        </surface>
      </collision>
      <collision name='base_footprint_fixed_joint_lump__imu_link_collision_2'>
        <pose>0 0 0.5650000000000001 0 0 0</pose>
        <geometry>
          <box>
            <size>0.05 0.05 0.05</size>
          </box>
        </geometry>
        <surface>
          <contact>
            <ode/>
          </contact>
          <friction>
            <ode/>
          </friction>
        </surface>
      </collision>
      <collision name='base_footprint_fixed_joint_lump__laser_link_collision_3'>
        <pose>0 0 0.765 0 0 0</pose>
        <geometry>
          <cylinder>
            <length>0.10000000000000001</length>
            <radius>0.10000000000000001</radius>
          </cylinder>
        </geometry>
        <surface>
          <contact>
            <ode/>
          </contact>
          <friction>
            <ode/>
          </friction>
        </surface>
      </collision>
      <visual name='base_footprint_fixed_joint_lump__base_link_visual'>
        <pose>0 0 0.365 0 0 0</pose>
        <geometry>
          <box>
            <size>2 1.2 0.4</size>
          </box>
        </geometry>
        <material>
          <diffuse>0 0 0 1</diffuse>
          <ambient>0 0 0 1</ambient>
        </material>
      </visual>
      <visual name='base_footprint_fixed_joint_lump__camera_gta_link_visual_1'>
        <pose>0 0 15.165 0 1.570796326794897 0</pose>
        <geometry>
          <box>
            <size>0.05 0.05 0.05</size>
          </box>
        </geometry>
        <material>
          <diffuse>0 0 0 1</diffuse>
          <ambient>0 0 0 1</ambient>
        </material>
      </visual>
      <visual name='base_footprint_fixed_joint_lump__camera_link_visual_2'>
        <pose>0.95 0 1.365 0 0.35 0</pose>
        <geometry>
          <box>
            <size>0.1 0.1 0.1</size>
          </box>
        </geometry>
        <material>
          <diffuse>0 0 1 1</diffuse>
          <ambient>0 0 1 1</ambient>
        </material>
      </visual>
      <visual name='base_footprint_fixed_joint_lump__imu_link_visual_3'>
        <pose>0 0 0.5650000000000001 0 0 0</pose>
        <geometry>
          <box>
            <size>0.05 0.05 0.05</size>
          </box>
        </geometry>
        <material>
          <diffuse>0 0 1 1</diffuse>
          <ambient>0 0 1 1</ambient>
        </material>
      </visual>
      <visual name='base_footprint_fixed_joint_lump__laser_link_visual_4'>
        <pose>0 0 0.765 0 0 0</pose>
        <geometry>
          <cylinder>
            <length>0.10000000000000001</length>
            <radius>0.10000000000000001</radius>
          </cylinder>
        </geometry>
        <material>
          <diffuse>0.375 0.375 0.375 1</diffuse>
          <ambient>0.375 0.375 0.375 1</ambient>
        </material>
      </visual>
      <sensor name='gta_camera' type='camera'>
        <update_rate>30</update_rate>
        <camera>
          <horizontal_fov>1.2</horizontal_fov>
          <image>
            <width>800</width>
            <height>600</height>
            <format>R8G8B8</format>
          </image>
          <clip>
            <near>0.10000000000000001</near>
            <far>200</far>
          </clip>
        </camera>
        <always_on>true</always_on>
        <visualize>true</visualize>
        <topic>/camera/gta_view</topic>
        <pose>0 0 15.165 0 1.5708 -0</pose>
        <frame_id>camera_gta_link</frame_id>
      </sensor>
      <sensor name='camera_sensor' type='camera'>
        <update_rate>30</update_rate>
        <camera>
          <horizontal_fov>1.5707</horizontal_fov>
          <image>
            <width>640</width>
            <height>480</height>
            <format>R8G8B8</format>
          </image>
          <clip>
            <near>0.10000000000000001</near>
            <far>50</far>
          </clip>
        </camera>
        <always_on>true</always_on>
        <visualize>true</visualize>
        <topic>/camera/image_raw</topic>
        <pose>0.95 0 1.365 0 0.35 0</pose>
        <frame_id>camera_link</frame_id>
      </sensor>
      <sensor name='imu_sensor' type='imu'>
        <always_on>true</always_on>
        <update_rate>100</update_rate>
        <visualize>true</visualize>
        <topic>/imu/data</topic>
        <pose>0 0 0.565 0 -0 0</pose>
        <gz_frame_id>imu_link</gz_frame_id>
      </sensor>
      <sensor name='lidar' type='gpu_lidar'>
        <topic>/scan</topic>
        <update_rate>10</update_rate>
        <ray>
          <scan>
            <horizontal>
              <samples>360</samples>
              <resolution>1</resolution>
              <min_angle>-3.1400000000000001</min_angle>
              <max_angle>3.1400000000000001</max_angle>
            </horizontal>
          </scan>
          <range>
            <min>0.20000000000000001</min>
            <max>30</max>
            <resolution>0.01</resolution>
          </range>
        </ray>
        <always_on>true</always_on>
        <visualize>true</visualize>
        <pose>0 0 0.765 0 -0 0</pose>
        <frame_id>laser_link</frame_id>
      </sensor>
    </link>
    <joint name='front_left_steering_joint' type='revolute'>
      <pose relative_to='base_footprint'>0.6 0.65 0.165 0 0 0</pose>
      <parent>base_footprint</parent>
      <child>front_left_steering_link</child>
      <axis>
        <xyz>0 0 1</xyz>
        <limit>
          <lower>-0.59999999999999998</lower>
          <upper>0.59999999999999998</upper>
          <effort>100</effort>
          <velocity>10</velocity>
        </limit>
        <dynamics>
          <spring_reference>0</spring_reference>
          <spring_stiffness>0</spring_stiffness>
        </dynamics>
      </axis>
    </joint>
    <link name='front_left_steering_link'>
      <pose relative_to='front_left_steering_joint'>0 0 0 0 0 0</pose>
      <inertial>
        <pose>0 0 0 0 0 0</pose>
        <mass>1</mass>
        <inertia>
          <ixx>0.01</ixx>
          <ixy>0</ixy>
          <ixz>0</ixz>
          <iyy>0.01</iyy>
          <iyz>0</iyz>
          <izz>0.01</izz>
        </inertia>
      </inertial>
    </link>
    <joint name='front_left_wheel_joint' type='revolute'>
      <pose relative_to='front_left_steering_link'>0 0 0 0 0 0</pose>
      <parent>front_left_steering_link</parent>
      <child>front_left_wheel_link</child>
      <axis>
        <xyz>0 1 0</xyz>
        <limit>
          <lower>-10000000000000000</lower>
          <upper>10000000000000000</upper>
        </limit>
        <dynamics>
          <spring_reference>0</spring_reference>
          <spring_stiffness>0</spring_stiffness>
        </dynamics>
      </axis>
    </joint>
    <link name='front_left_wheel_link'>
      <pose relative_to='front_left_wheel_joint'>0 0 0 0 0 0</pose>
      <inertial>
        <pose>0 0 0 0 0 0</pose>
        <mass>5</mass>
        <inertia>
          <ixx>0.068000000000000005</ixx>
          <ixy>0</ixy>
          <ixz>0</ixz>
          <iyy>0.068000000000000005</iyy>
          <iyz>0</iyz>
          <izz>0.068000000000000005</izz>
        </inertia>
      </inertial>
      <collision name='front_left_wheel_link_collision'>
        <pose>0 0 0 -1.57 0 0</pose>
        <geometry>
          <cylinder>
            <length>0.10000000000000001</length>
            <radius>0.16500000000000001</radius>
          </cylinder>
        </geometry>
        <surface>
          <contact>
            <ode>
              <kp>5000</kp>
              <kd>80</kd>
              <min_depth>0.01</min_depth>
            </ode>
          </contact>
          <friction>
            <ode>
              <mu>1</mu>
              <mu2>1</mu2>
            </ode>
          </friction>
        </surface>
      </collision>
      <visual name='front_left_wheel_link_visual'>
        <pose>0 0 0 -1.57 0 0</pose>
        <geometry>
          <cylinder>
            <length>0.10000000000000001</length>
            <radius>0.16500000000000001</radius>
          </cylinder>
        </geometry>
        <material>
          <script>
            <name>Gazebo/Blue</name>
            <uri>file://media/materials/scripts/gazebo.material</uri>
          </script>
          <diffuse>0 0 1 1</diffuse>
          <ambient>0 0 1 1</ambient>
        </material>
      </visual>
    </link>
    <joint name='front_right_steering_joint' type='revolute'>
      <pose relative_to='base_footprint'>0.6 -0.65 0.165 0 0 0</pose>
      <parent>base_footprint</parent>
      <child>front_right_steering_link</child>
      <axis>
        <xyz>0 0 1</xyz>
        <limit>
          <lower>-0.59999999999999998</lower>
          <upper>0.59999999999999998</upper>
          <effort>100</effort>
          <velocity>10</velocity>
        </limit>
        <dynamics>
          <spring_reference>0</spring_reference>
          <spring_stiffness>0</spring_stiffness>
        </dynamics>
      </axis>
    </joint>
    <link name='front_right_steering_link'>
      <pose relative_to='front_right_steering_joint'>0 0 0 0 0 0</pose>
      <inertial>
        <pose>0 0 0 0 0 0</pose>
        <mass>1</mass>
        <inertia>
          <ixx>0.01</ixx>
          <ixy>0</ixy>
          <ixz>0</ixz>
          <iyy>0.01</iyy>
          <iyz>0</iyz>
          <izz>0.01</izz>
        </inertia>
      </inertial>
    </link>
    <joint name='front_right_wheel_joint' type='revolute'>
      <pose relative_to='front_right_steering_link'>0 0 0 0 0 0</pose>
      <parent>front_right_steering_link</parent>
      <child>front_right_wheel_link</child>
      <axis>
        <xyz>0 1 0</xyz>
        <limit>
          <lower>-10000000000000000</lower>
          <upper>10000000000000000</upper>
        </limit>
        <dynamics>
          <spring_reference>0</spring_reference>
          <spring_stiffness>0</spring_stiffness>
        </dynamics>
      </axis>
    </joint>
    <link name='front_right_wheel_link'>
      <pose relative_to='front_right_wheel_joint'>0 0 0 0 0 0</pose>
      <inertial>
        <pose>0 0 0 0 0 0</pose>
        <mass>5</mass>
        <inertia>
          <ixx>0.068000000000000005</ixx>
          <ixy>0</ixy>
          <ixz>0</ixz>
          <iyy>0.068000000000000005</iyy>
          <iyz>0</iyz>
          <izz>0.068000000000000005</izz>
        </inertia>
      </inertial>
      <collision name='front_right_wheel_link_collision'>
        <pose>0 0 0 1.57 0 0</pose>
        <geometry>
          <cylinder>
            <length>0.10000000000000001</length>
            <radius>0.16500000000000001</radius>
          </cylinder>
        </geometry>
        <surface>
          <contact>
            <ode>
              <kp>5000</kp>
              <kd>80</kd>
              <min_depth>0.01</min_depth>
            </ode>
          </contact>
          <friction>
            <ode>
              <mu>1</mu>
              <mu2>1</mu2>
            </ode>
          </friction>
        </surface>
      </collision>
      <visual name='front_right_wheel_link_visual'>
        <pose>0 0 0 1.57 0 0</pose>
        <geometry>
          <cylinder>
            <length>0.10000000000000001</length>
            <radius>0.16500000000000001</radius>
          </cylinder>
        </geometry>
        <material>
          <script>
            <name>Gazebo/Blue</name>
            <uri>file://media/materials/scripts/gazebo.material</uri>
          </script>
          <diffuse>0 0 1 1</diffuse>
          <ambient>0 0 1 1</ambient>
        </material>
      </visual>
    </link>
    <joint name='rear_left_wheel_joint' type='revolute'>
      <pose relative_to='base_footprint'>-0.6 0.65 0.165 0 0 0</pose>
      <parent>base_footprint</parent>
      <child>rear_left_wheel_link</child>
      <axis>
        <xyz>0 1 0</xyz>
        <limit>
          <lower>-1e16</lower>
          <upper>1e16</upper>
          <effort>1000</effort>
          <velocity>50</velocity>
        </limit>
        <dynamics>
          <spring_reference>0</spring_reference>
          <spring_stiffness>0</spring_stiffness>
          <damping>0.1</damping>
        </dynamics>
      </axis>
    </joint>
    <link name='rear_left_wheel_link'>
      <pose relative_to='rear_left_wheel_joint'>0 0 0 0 0 0</pose>
      <inertial>
        <pose>0 0 0 0 0 0</pose>
        <mass>5</mass>
        <inertia>
          <ixx>0.068000000000000005</ixx>
          <ixy>0</ixy>
          <ixz>0</ixz>
          <iyy>0.068000000000000005</iyy>
          <iyz>0</iyz>
          <izz>0.068000000000000005</izz>
        </inertia>
      </inertial>
      <collision name='rear_left_wheel_link_collision'>
        <pose>0 0 0 -1.57 0 0</pose>
        <geometry>
          <cylinder>
            <length>0.10000000000000001</length>
            <radius>0.16500000000000001</radius>
          </cylinder>
        </geometry>
        <surface>
          <contact>
            <ode>
              <kp>5000</kp>
              <kd>80</kd>
              <min_depth>0.01</min_depth>
            </ode>
          </contact>
          <friction>
            <ode>
              <mu>1.5</mu>
              <mu2>1.5</mu2>
            </ode>
          </friction>
        </surface>
      </collision>
      <visual name='rear_left_wheel_link_visual'>
        <pose>0 0 0 -1.57 0 0</pose>
        <geometry>
          <cylinder>
            <length>0.10000000000000001</length>
            <radius>0.16500000000000001</radius>
          </cylinder>
        </geometry>
        <material>
          <script>
            <name>Gazebo/Blue</name>
            <uri>file://media/materials/scripts/gazebo.material</uri>
          </script>
          <diffuse>0 0 1 1</diffuse>
          <ambient>0 0 1 1</ambient>
        </material>
      </visual>
    </link>
    <joint name='rear_right_wheel_joint' type='revolute'>
      <pose relative_to='base_footprint'>-0.6 -0.65 0.165 0 0 0</pose>
      <parent>base_footprint</parent>
      <child>rear_right_wheel_link</child>
      <axis>
        <xyz>0 1 0</xyz>
        <limit>
          <lower>-1e16</lower>
          <upper>1e16</upper>
          <effort>1000</effort>
          <velocity>50</velocity>
        </limit>
        <dynamics>
          <spring_reference>0</spring_reference>
          <spring_stiffness>0</spring_stiffness>
          <damping>0.1</damping>
        </dynamics>
      </axis>
    </joint>
    <link name='rear_right_wheel_link'>
      <pose relative_to='rear_right_wheel_joint'>0 0 0 0 0 0</pose>
      <inertial>
        <pose>0 0 0 0 0 0</pose>
        <mass>5</mass>
        <inertia>
          <ixx>0.068000000000000005</ixx>
          <ixy>0</ixy>
          <ixz>0</ixz>
          <iyy>0.068000000000000005</iyy>
          <iyz>0</iyz>
          <izz>0.068000000000000005</izz>
        </inertia>
      </inertial>
      <collision name='rear_right_wheel_link_collision'>
        <pose>0 0 0 1.57 0 0</pose>
        <geometry>
          <cylinder>
            <length>0.10000000000000001</length>
            <radius>0.16500000000000001</radius>
          </cylinder>
        </geometry>
        <surface>
          <contact>
            <ode>
              <kp>5000</kp>
              <kd>80</kd>
              <min_depth>0.01</min_depth>
            </ode>
          </contact>
          <friction>
            <ode>
              <mu>1.5</mu>
              <mu2>1.5</mu2>
            </ode>
          </friction>
        </surface>
      </collision>
      <visual name='rear_right_wheel_link_visual'>
        <pose>0 0 0 1.57 0 0</pose>
        <geometry>
          <cylinder>
            <length>0.10000000000000001</length>
            <radius>0.16500000000000001</radius>
          </cylinder>
        </geometry>
        <material>
          <script>
            <name>Gazebo/Blue</name>
            <uri>file://media/materials/scripts/gazebo.material</uri>
          </script>
          <diffuse>0 0 1 1</diffuse>
          <ambient>0 0 1 1</ambient>
        </material>
      </visual>
    </link>
    <plugin name='ignition::gazebo::systems::VelocityControl' filename='libignition-gazebo-velocity-control-system.so'>
      <topic>/model/my_robot/cmd_vel</topic>
    </plugin>
    <plugin name='ignition::gazebo::systems::Sensors' filename='libignition-gazebo-sensors-system.so'>
      <render_engine>ogre2</render_engine>
    </plugin>
    <plugin name='ignition::gazebo::systems::Imu' filename='libignition-gazebo-imu-system.so'/>
    <plugin name='ignition::gazebo::systems::JointStatePublisher' filename='libignition-gazebo-joint-state-publisher-system.so'>
      <topic>joint_states</topic>
    </plugin>
    <frame name='camera_gta_joint' attached_to='base_link'>
      <pose>0 0 15 0 1.5707 0</pose>
    </frame>
    <frame name='camera_gta_link' attached_to='camera_gta_joint'/>
    <frame name='camera_joint' attached_to='base_link'>
      <pose>0.95 0 1.2 0 0.35 0</pose>
    </frame>
    <frame name='camera_link' attached_to='camera_joint'/>
    <frame name='imu_joint' attached_to='base_link'>
      <pose>0 0 0.4 0 -0 0</pose>
    </frame>
    <frame name='imu_link' attached_to='imu_joint'/>
    <frame name='laser_joint' attached_to='base_link'>
      <pose>0 0 0.6 0 -0 0</pose>
    </frame>
    <frame name='laser_link' attached_to='laser_joint'/>
    <frame name='base_joint' attached_to='base_footprint'>
      <pose>0 0 0.165 0 -0 0</pose>
    </frame>
    <frame name='base_link' attached_to='base_joint'/>

  </model>

  </world>
</sdf>
